/*
 * Copyright 2016-2018 JetBrains s.r.o. Use of this source code is governed by the Apache 2.0 license.
 */

// This file was automatically generated from coroutines-guide.md by Knit tool. Do not edit.
package kotlinx.coroutines.experimental.guide.exceptions01

import kotlinx.coroutines.experimental.*

fun main(args: Array<String>) = runBlocking {
    val job = GlobalScope.launch {
        println("Throwing exception from launch")
        throw IndexOutOfBoundsException() // Will be printed to the console by Thread.defaultUncaughtExceptionHandler
    }
    job.join()
    println("Joined failed job")
    val deferred = GlobalScope.async {
        println("Throwing exception from async")
        throw ArithmeticException() // Nothing is printed, relying on user to call await
    }
    try {
        deferred.await()
        println("Unreached")
    } catch (e: ArithmeticException) {
        println("Caught ArithmeticException")
    }
}
