kotlinx.coroutines.RecoverableTestException
	at kotlinx.coroutines.exceptions.StackTraceRecoveryResumeModeTest.testResumeModeFastPath(StackTraceRecoveryResumeModeTest.kt:61)
	at kotlinx.coroutines.exceptions.StackTraceRecoveryResumeModeTest$testNestedUnconfined$1$1.invokeSuspend(StackTraceRecoveryResumeModeTest.kt:27)
	(Coroutine boundary)
	at kotlinx.coroutines.exceptions.StackTraceRecoveryResumeModeTest$withContext$2.invokeSuspend(StackTraceRecoveryResumeModeTest.kt:76)
	at kotlinx.coroutines.exceptions.StackTraceRecoveryResumeModeTest.doFastPath(StackTraceRecoveryResumeModeTest.kt:71)
	at kotlinx.coroutines.exceptions.StackTraceRecoveryResumeModeTest.testResumeModeFastPath(StackTraceRecoveryResumeModeTest.kt:62)
	at kotlinx.coroutines.exceptions.StackTraceRecoveryResumeModeTest$testNestedUnconfined$1$1.invokeSuspend(StackTraceRecoveryResumeModeTest.kt:27)
	at kotlinx.coroutines.exceptions.StackTraceRecoveryResumeModeTest$testNestedUnconfined$1.invokeSuspend(StackTraceRecoveryResumeModeTest.kt:26)
Caused by: kotlinx.coroutines.RecoverableTestException
	at kotlinx.coroutines.exceptions.StackTraceRecoveryResumeModeTest.testResumeModeFastPath(StackTraceRecoveryResumeModeTest.kt:61)
	at kotlinx.coroutines.exceptions.StackTraceRecoveryResumeModeTest$testNestedUnconfined$1$1.invokeSuspend(StackTraceRecoveryResumeModeTest.kt:27)
	at kotlin.coroutines.jvm.internal.BaseContinuationImpl.resumeWith(ContinuationImpl.kt:33)